Workbook
Name Alimentacao: Aux_Listas!$H$2:$H$5
Name Alimentação: Aux_Listas!$H$2:$H$20
Name Beneficio: Aux_Listas!$C$2:$C$2
Name Benefício: Aux_Listas!$C$2:$C$20
Name Caridade: Aux_Listas!$O$2:$O$20
Name Cartoes_Credito: FATURAS_CARTAO!$A$4:$A$6
Name Categorias_Despesa: Aux_Listas!$A$6:$A$16
Name Categorias_Receita: Aux_Listas!$A$1:$A$5
Name Convênio: Aux_Listas!$E$2:$E$20
Name Convenios: Aux_Listas!$E$2:$E$2
Name Convênios: Aux_Listas!$E$2:$E$20
Name Dividas: Aux_Listas!$P$2:$P$3
Name Dívidas: Aux_Listas!$P$2:$P$20
Name Educacao: Aux_Listas!$K$2:$K$7
Name Educação: Aux_Listas!$K$2:$K$20
Name Extra: Aux_Listas!$F$2:$F$20
Name Habitacao: Aux_Listas!$G$2:$G$16
Name Habitação: Aux_Listas!$G$2:$G$20
Name Invest_Alternativos: Aux_Listas!$U$2:$U$20
Name Lazer: Aux_Listas!$M$2:$M$20
Name listaCategorias: Aux_Listas!$A$1:INDEX(Aux_Listas!$A:$A,COUNTA(Aux_Listas!$A:$A))
Name Outras_Despesas: Aux_Listas!$Q$2:$Q$20
Name Outros: Aux_Listas!$Q$2:$Q$20
Name Previdência: Aux_Listas!$T$2:$T$20
Name Renda_Fixa: Aux_Listas!$R$2:$R$20
Name Renda_Variável: Aux_Listas!$S$2:$S$20
Name Rentda_Fixa: Aux_Listas!$R$2:$R$20
Name Salario: Aux_Listas!$B$2:$B$7
Name Salário: Aux_Listas!$B$2:$B$7
Name Saude: Aux_Listas!$J$2:$J$6
Name Saúde: Aux_Listas!$J$2:$J$20
Name Servico: Aux_Listas!$D$2:$D$2
Name tbReceitas: LAN_RECEITAS!$A$4:$E$57
Name Trabalho: Aux_Listas!$N$2:$N$20
Name Transporte: Aux_Listas!$I$2:$I$20
Name Vestuario: Aux_Listas!$L$2:$L$4
Name Vestuário: Aux_Listas!$L$2:$L$20

Sheet INICIO
A1: 📊 SISTEMA DE ORÇAMENTO DOMÉSTICO - GUIA DE USO
A2: Controle Financeiro Pessoal - Versão 1.0 | Template para GitHub
A4: 📝 COMO LANÇAR SEUS DADOS
A6: Aba | B6: O que lançar | C6: Campos obrigatórios | D6: Observações
A7: LAN_RECEITAS | B7: Salários, benefícios, rendas extras | C7: Data, Categoria, Subcategoria, Valor, Status | D7: Observação opcional
A8: LAN_DESPESAS | B8: Despesas pagas à vista (Débito/PIX) | C8: Data, Categoria, Subcategoria, Valor, Observação, Status | D8: Use para pagamentos imediatos
A9: LAN_CARTOES | B9: Compras no cartão de crédito | C9: Data_Compra, Categoria, Valor_Total, N_Parcelas, Cartão | D9: Parcelas geradas automaticamente
A10: LAN_INVESTIMENTOS | B10: Aportes e resgates | C10: Data, Ativo, Movimento, Valor | D10: Tipo_Ativo preenche automaticamente
A12: 💳 SISTEMA DE CARTÃO DE CRÉDITO
A14: ✅ PASSO 1: Lance a compra na aba LAN_CARTOES (colunas A-H)
A15: ✅ PASSO 2: Verifique a coluna I (Status_Parcelas)
A16: → ✅ Gerada = Parcelas já existem na aba PARCELAS
A17: → ⚠️ Pendente = Peça para gerar parcelas
A18: ✅ PASSO 3: Se houver pendentes, peça: 'Gerar parcelas'
A19: ✅ PASSO 4: FLUXO_CAIXA mostra saídas nas datas de vencimento
A20: 💡 DICA: O contador no topo da aba mostra quantas estão pendentes!
A22: 📊 VISUALIZAÇÃO E RELATÓRIOS
A24: Aba | B24: Função | C24: Como usar
A25: DASHBOARD | B25: KPIs, gráficos e comparativos | C25: Use filtros ANO e MÊS
A26: ORCAMENTO | B26: Previsto x Realizado mensal | C26: Selecione ANO em R1
A27: FLUXO_CAIXA | B27: Fluxo de caixa MENSAL + PRÓXIMOS 30 DIAS | C27: B4 = Saldo em 01/01 | Saldo atual calculado automaticamente
A29: ⚙️ CADASTROS E CONFIGURAÇÕES
A31: • CAD_Categorias - Cadastro de categorias e subcategorias
A32: • FATURAS_CARTAO - Configuração dos cartões de crédito (corte/vencimento) e lista de cartões
A33: • CAD_Ativos - Tipos de ativos para investimentos
A34: • Aux_Listas - Listas auxiliares para dropdowns (não alterar)
A36: 📊 SISTEMA DE PREVISÕES
A38: A aba PREVISOES contém todas as previsões de receitas e despesas futuras.
A39: Cada mês tem uma linha separada para fácil controle.
A41: Como usar:
A42: 1. As previsões são lançadas diretamente na aba PREVISOES
A43: 2. Cada linha = 1 mês de previsão
A44: 3. Quando realizar um lançamento, marque a previsão como 'Cancelada'
... A115: • Se já existir previsão para o mês, será substituída

Sheet ORCAMENTO
A1: ORÇAMENTO 2025
A2: 📋 Categoria | B2: 💰 Prev.Mensal | C2: =DATE($R$2,1,1) -> 45658 | D2: =DATE($R$2,2,1) -> 45689 | E2: =DATE($R$2,3,1) -> 45717 | F2: =DATE($R$2,4,1) -> 45748 | G2: =DATE($R$2,5,1) -> 45778 | H2: =DATE($R$2,6,1) -> 45809 | I2: =DATE($R$2,7,1) -> 45839 | J2: =DATE($R$2,8,1) -> 45870 | K2: =DATE($R$2,9,1) -> 45901 | L2: =DATE($R$2,10,1) -> 45931 | M2: =DATE($R$2,11,1) -> 45962 | N2: =DATE($R$2,12,1) -> 45992 | O2: 📊 Anual | P2: 📈 Média | Q2: 📅 ANO: | R2: 2025
A3: Receitas | B3: =B4+B11+B12+B13+B14 -> 16000 | C3: =C4+C11+C12+C13+C14 -> 16200 | D3: =D4+D11+D12+D13+D14 -> 15900 | E3: =E4+E11+E12+E13+E14 -> 16400 | F3: =F4+F11+F12+F13+F14 -> 16000 | G3: =G4+G11+G12+G13+G14 -> 16150 | H3: =H4+H11+H12+H13+H14 -> 15950 | I3: =I4+I11+I12+I13+I14 -> 16000 | ... N3: =N4+N11+N12+N13+N14 -> 17100 | O3: =SUM(C3:N3) -> 194500 | P3: =IF(MONTH(TODAY())>0, O3/MONTH(TODAY()), 0) -> 38900
A4: Salário | B4: =SUM(B5:B10) -> 15000 | C4: =SUM(C5:C10) -> 15000 | D4: =SUM(D5:D10) -> 15000 | E4: =SUM(E5:E10) -> 15000 | F4: =SUM(F5:F10) -> 15000 | G4: =SUM(G5:G10) -> 15000 | H4: =SUM(H5:H10) -> 15000 | I4: =SUM(I5:I10) -> 15000 | ... N4: =SUM(N5:N10) -> 15000 | O4: =SUM(C4:N4) -> 180000 | P4: =IF(MONTH(TODAY())>0, O4/MONTH(TODAY()), 0) -> 36000
A5: Salário Marido | B5: 8500 | C5: 8500 | D5: 8500 | E5: 8500 | F5: 8500 | G5: 8500 | H5: 8500 | I5: 8500 | J5: 8500 | K5: 8500 | L5: 8500 | M5: 8500 | N5: 8500 | O5: =SUM(C5:N5) -> 102000 | P5: =IF(MONTH(TODAY())>0, O5/MONTH(TODAY()), 0) -> 20400
A6: Salário Esposa | B6: 6500 | C6: 6500 | D6: 6500 | E6: 6500 | F6: 6500 | G6: 6500 | H6: 6500 | I6: 6500 | J6: 6500 | K6: 6500 | L6: 6500 | M6: 6500 | N6: 6500 | O6: =SUM(C6:N6) -> 78000 | P6: =IF(MONTH(TODAY())>0, O6/MONTH(TODAY()), 0) -> 15600
B7: 0 | C7: 0 | D7: 0 | E7: 0 | F7: 0 | G7: 0 | H7: 0 | I7: 0 | J7: 0 | K7: 0 | L7: 0 | M7: 0 | N7: 0 | O7: =SUM(C7:N7) -> 0 | P7: =IF(MONTH(TODAY())>0, O7/MONTH(TODAY()), 0) -> 0
B8: 0 | C8: 0 | D8: 0 | E8: 0 | F8: 0 | G8: 0 | H8: 0 | I8: 0 | J8: 0 | K8: 0 | L8: 0 | M8: 0 | N8: 0 | O8: =SUM(C8:N8) -> 0 | P8: =IF(MONTH(TODAY())>0, O8/MONTH(TODAY()), 0) -> 0
B9: 0 | C9: 0 | D9: 0 | E9: 0 | F9: 0 | G9: 0 | H9: 0 | I9: 0 | J9: 0 | K9: 0 | L9: 0 | M9: 0 | N9: 0 | O9: =SUM(C9:N9) -> 0 | P9: =IF(MONTH(TODAY())>0, O9/MONTH(TODAY()), 0) -> 0
B10: 0 | C10: 0 | D10: 0 | E10: 0 | F10: 0 | G10: 0 | H10: 0 | I10: 0 | J10: 0 | K10: 0 | L10: 0 | M10: 0 | N10: 0 | O10: =SUM(C10:N10) -> 0 | P10: =IF(MONTH(TODAY())>0, O10/MONTH(TODAY()), 0) -> 0
A11: Benefício | B11: 500 | C11: 500 | D11: 500 | E11: 500 | F11: 500 | G11: 500 | H11: 500 | I11: 500 | J11: 500 | K11: 500 | L11: 500 | M11: 500 | N11: 500 | O11: =SUM(C11:N11) -> 6000 | P11: =IF(MONTH(TODAY())>0, O11/MONTH(TODAY()), 0) -> 1200
A12: Convênios | B12: 0 | C12: 0 | D12: 0 | E12: 0 | F12: 0 | G12: 0 | H12: 0 | I12: 0 | J12: 0 | K12: 0 | L12: 0 | M12: 0 | N12: 0 | O12: =SUM(C12:N12) -> 0 | P12: =IF(MONTH(TODAY())>0, O12/MONTH(TODAY()), 0) -> 0
A13: Extra | B13: 0 | C13: 200 | D13: 0 | E13: 300 | F13: 0 | G13: 150 | H13: 0 | I13: 0 | J13: 250 | K13: 0 | L13: 0 | M13: 500 | N13: 1000 | O13: =SUM(C13:N13) -> 2400 | P13: =IF(MONTH(TODAY())>0, O13/MONTH(TODAY()), 0) -> 480
A14: Prestação Serviço Extra | B14: 500 | C14: 500 | D14: 400 | E14: 600 | F14: 500 | G14: 500 | H14: 450 | I14: 500 | J14: 500 | K14: 550 | L14: 500 | M14: 500 | N14: 600 | O14: =SUM(C14:N14) -> 6100 | P14: =IF(MONTH(TODAY())>0, O14/MONTH(TODAY()), 0) -> 1220
A15: Investimentos | B15: 500 | C15: =SUM(C16:C19) -> 500 | D15: =SUM(D16:D19) -> 500 | E15: =SUM(E16:E19) -> 500 | F15: =SUM(F16:F19) -> 500 | G15: =SUM(G16:G19) -> 500 | H15: =SUM(H16:H19) -> 500 | I15: =SUM(I16:I19) -> 500 | J15: =SUM(J16:J19) -> 500 | ... N15: =SUM(N16:N19) -> 700 | O15: =SUM(C15:N15) -> 6200 | P15: =IF(MONTH(TODAY())>0, O15/MONTH(TODAY()), 0) -> 1240
A16: Renda Fixa | B16: 300 | C16: 300 | D16: 300 | E16: 300 | F16: 300 | G16: 300 | H16: 300 | I16: 300 | J16: 300 | K16: 300 | L16: 300 | M16: 300 | N16: 500 | O16: =SUM(C16:N16) -> 3800 | P16: =IF(MONTH(TODAY())>0, O16/MONTH(TODAY()), 0) -> 760
A17: Renda Variável | B17: 100 | C17: 100 | D17: 100 | E17: 100 | F17: 100 | G17: 100 | H17: 100 | I17: 100 | J17: 100 | K17: 100 | L17: 100 | M17: 100 | N17: 100 | O17: =SUM(C17:N17) -> 1200 | P17: =IF(MONTH(TODAY())>0, O17/MONTH(TODAY()), 0) -> 240
A18: Previdência | B18: 100 | C18: 100 | D18: 100 | E18: 100 | F18: 100 | G18: 100 | H18: 100 | I18: 100 | J18: 100 | K18: 100 | L18: 100 | M18: 100 | N18: 100 | O18: =SUM(C18:N18) -> 1200 | P18: =IF(MONTH(TODAY())>0, O18/MONTH(TODAY()), 0) -> 240
A19: Alternativos | B19: 0 | C19: 0 | D19: 0 | E19: 0 | F19: 0 | G19: 0 | H19: 0 | I19: 0 | J19: 0 | K19: 0 | L19: 0 | M19: 0 | N19: 0 | O19: =SUM(C19:N19) -> 0 | P19: =IF(MONTH(TODAY())>0, O19/MONTH(TODAY()), 0) -> 0
A20: Despesas | B20: =SUM(B21:B31) -> 12500 | C20: =SUM(C21:C31) -> 12130 | D20: =SUM(D21:D31) -> 13020 | E20: =SUM(E21:E31) -> 11750 | F20: =SUM(F21:F31) -> 13100 | G20: =SUM(G21:G31) -> 12500 | H20: =SUM(H21:H31) -> 12320 | I20: =SUM(I21:I31) -> 12760 | ... N20: =SUM(N21:N31) -> 13800 | O20: =SUM(C20:N20) -> 151680 | P20: =IF(MONTH(TODAY())>0, O20/MONTH(TODAY()), 0) -> 30336
A21: Habitação | B21: 4800 | C21: 4750 | D21: 4850 | E21: 4700 | F21: 4900 | G21: 4800 | H21: 4750 | I21: 4850 | J21: 4700 | K21: 4800 | L21: 4900 | M21: 4750 | N21: 5000 | O21: =SUM(C21:N21) -> 57750 | P21: =IF(MONTH(TODAY())>0, O21/MONTH(TODAY()), 0) -> 11550
A22: Alimentação | B22: 2000 | C22: 1950 | D22: 2100 | E22: 1900 | F22: 2050 | G22: 2000 | H22: 1980 | I22: 2100 | J22: 1900 | K22: 2000 | L22: 2050 | M22: 2100 | N22: 2200 | O22: =SUM(C22:N22) -> 24330 | P22: =IF(MONTH(TODAY())>0, O22/MONTH(TODAY()), 0) -> 4866
A23: Transporte | B23: 1200 | C23: 1150 | D23: 1250 | E23: 1100 | F23: 1300 | G23: 1200 | H23: 1180 | I23: 1220 | J23: 1150 | K23: 1200 | L23: 1250 | M23: 1200 | N23: 1300 | O23: =SUM(C23:N23) -> 14500 | P23: =IF(MONTH(TODAY())>0, O23/MONTH(TODAY()), 0) -> 2900
A24: Saúde | B24: 800 | C24: 750 | D24: 850 | E24: 700 | F24: 900 | G24: 800 | H24: 780 | I24: 820 | J24: 750 | K24: 800 | L24: 850 | M24: 800 | N24: 900 | O24: =SUM(C24:N24) -> 9700 | P24: =IF(MONTH(TODAY())>0, O24/MONTH(TODAY()), 0) -> 1940
A25: Educação | B25: 1500 | C25: 1500 | D25: 1500 | E25: 1500 | F25: 1500 | G25: 1500 | H25: 1500 | I25: 1500 | J25: 1500 | K25: 1500 | L25: 1500 | M25: 1500 | N25: 1500 | O25: =SUM(C25:N25) -> 18000 | P25: =IF(MONTH(TODAY())>0, O25/MONTH(TODAY()), 0) -> 3600
A26: Vestuário | B26: 300 | C26: 250 | D26: 350 | E26: 200 | F26: 400 | G26: 300 | H26: 280 | I26: 320 | J26: 250 | K26: 300 | L26: 350 | M26: 400 | N26: 500 | O26: =SUM(C26:N26) -> 3900 | P26: =IF(MONTH(TODAY())>0, O26/MONTH(TODAY()), 0) -> 780
A27: Lazer | B27: 600 | C27: 550 | D27: 700 | E27: 500 | F27: 650 | G27: 600 | H27: 580 | I27: 620 | J27: 550 | K27: 600 | L27: 650 | M27: 700 | N27: 800 | O27: =SUM(C27:N27) -> 7500 | P27: =IF(MONTH(TODAY())>0, O27/MONTH(TODAY()), 0) -> 1500
A28: Caridade | B28: 100 | C28: 100 | D28: 100 | E28: 100 | F28: 100 | G28: 100 | H28: 100 | I28: 100 | J28: 100 | K28: 100 | L28: 100 | M28: 100 | N28: 150 | O28: =SUM(C28:N28) -> 1250 | P28: =IF(MONTH(TODAY())>0, O28/MONTH(TODAY()), 0) -> 250
A29: Gastos Profissionais | B29: 200 | C29: 180 | D29: 220 | E29: 150 | F29: 250 | G29: 200 | H29: 190 | I29: 210 | J29: 180 | K29: 200 | L29: 220 | M29: 200 | N29: 250 | O29: =SUM(C29:N29) -> 2450 | P29: =IF(MONTH(TODAY())>0, O29/MONTH(TODAY()), 0) -> 490
A30: Dívidas | B30: 0 | C30: 0 | D30: 0 | E30: 0 | F30: 0 | G30: 0 | H30: 0 | I30: 0 | J30: 0 | K30: 0 | L30: 0 | M30: 0 | N30: 0 | O30: =SUM(C30:N30) -> 0 | P30: =IF(MONTH(TODAY())>0, O30/MONTH(TODAY()), 0) -> 0
A31: Outros | B31: 1000 | C31: 950 | D31: 1100 | E31: 900 | F31: 1050 | G31: 1000 | H31: 980 | I31: 1020 | J31: 950 | K31: 1000 | L31: 1050 | M31: 1100 | N31: 1200 | O31: =SUM(C31:N31) -> 12300 | P31: =IF(MONTH(TODAY())>0, O31/MONTH(TODAY()), 0) -> 2460
A32: Resultado Operacional | B32: =B3-B20 -> 3500 | C32: =C3-C20 -> 4070 | D32: =D3-D20 -> 2880 | E32: =E3-E20 -> 4650 | F32: =F3-F20 -> 2900 | G32: =G3-G20 -> 3650 | H32: =H3-H20 -> 3630 | I32: =I3-I20 -> 3240 | ... N32: =N3-N20 -> 3300 | O32: =SUM(C32:N32) -> 42820 | P32: =IF(MONTH(TODAY())>0, O32/MONTH(TODAY()), 0) -> 8564
A33: Resultado c/ Investimentos | B33: =B3-B20-B15 -> 3000 | C33: =C3-C20-C15 -> 3570 | D33: =D3-D20-D15 -> 2380 | E33: =E3-E20-E15 -> 4150 | F33: =F3-F20-F15 -> 2400 | G33: =G3-G20-G15 -> 3150 | H33: =H3-H20-H15 -> 3130 | I33: =I3-I20-I15 -> 2740 | ... N33: =N3-N20-N15 -> 2600 | O33: =SUM(C33:N33) -> 36620 | P33: =IF(MONTH(TODAY())>0, O33/MONTH(TODAY()), 0) -> 7324

Sheet LAN_RECEITAS
A1: 📥 LANÇAMENTOS DE RECEITAS
A2: Controle de Entradas Financeiras - Salários, Benefícios, Serviços e Extras
A3: 📅 Data | B3: 📂 Categoria | C3: 📋 Subcategoria | D3: 💵 Valor | E3: 📝 Observação | F3: 📊 Status
A4: 45661 | B4: Salário | C4: Salário Marido | D4: 8500 | E4: Salário mensal | F4: Realizado
A5: 45666 | B5: Salário | C5: Salário Esposa | D5: 6500 | E5: Salário mensal | F5: Realizado
A6: 45657 | B6: Benefício | C6: Auxílio Alimentação | D6: 500 | E6: Vale alimentação | F6: Realizado
A7: 45681 | B7: Prestação Serviço Extra | C7: Serviço Freelance | D7: 500 | E7: Trabalho extra | F7: Realizado
A8: 45671 | B8: Extra | C8: Outros | D8: 200 | E8: Receita extra | F8: Realizado
A9: 45692 | B9: Salário | C9: Salário Marido | D9: 8500 | E9: Salário mensal | F9: Realizado
A10: 45697 | B10: Salário | C10: Salário Esposa | D10: 6500 | E10: Salário mensal | F10: Realizado
A11: 45688 | B11: Benefício | C11: Auxílio Alimentação | D11: 500 | E11: Vale alimentação | F11: Realizado
A12: 45712 | B12: Prestação Serviço Extra | C12: Serviço Freelance | D12: 400 | E12: Trabalho extra | F12: Realizado
A13: 45720 | B13: Salário | C13: Salário Marido | D13: 8500 | E13: Salário mensal | F13: Realizado
A14: 45725 | B14: Salário | C14: Salário Esposa | D14: 6500 | E14: Salário mensal | F14: Realizado
A15: 45716 | B15: Benefício | C15: Auxílio Alimentação | D15: 500 | E15: Vale alimentação | F15: Realizado
... A57: 46005 | B57: Extra | C57: Outros | D57: 1000 | E57: Receita extra | F57: Realizado

Sheet LAN_DESPESAS
A1: 📤 LANÇAMENTOS DE DESPESAS
A2: Controle de Saídas Financeiras - Pagamentos à Vista (Débito/PIX)
A3: 📅 Data | B3: 📂 Categoria | C3: 📋 Subcategoria | D3: 💰 Valor | E3: 📝 Observação | F3: Categoria_Aux | G3: 📊 Status
A4: 45666 | B4: Habitação | C4: Aluguel/Financiamento | D4: 2375 | E4: Financiamento casa | F4: Habitacao | G4: Realizado
A5: 45671 | B5: Habitação | C5: Energia Elétrica | D5: 712.5 | E5: Conta de luz | F5: Habitacao | G5: Realizado
A6: 45676 | B6: Habitação | C6: Água | D6: 380 | E6: Conta de água | F6: Habitacao | G6: Realizado
A7: 45681 | B7: Habitação | C7: Internet / TV | D7: 570 | E7: Internet e TV | F7: Habitacao | G7: Realizado
A8: 45684 | B8: Habitação | C8: Condomínio | D8: 712.5 | E8: Taxa condomínio | F8: Habitacao | G8: Realizado
A9: 45661 | B9: Alimentação | C9: Supermercado | D9: 1365 | E9: Compras do mês | F9: Alimentacao | G9: Realizado
A10: 45674 | B10: Alimentação | C10: Padaria | D10: 292.5 | E10: Padaria | F10: Alimentacao | G10: Realizado
A11: 45678 | B11: Alimentação | C11: Restaurante | D11: 292.5 | E11: Almoço fora | F11: Alimentacao | G11: Realizado
A12: 45664 | B12: Transporte | C12: Gasolina | D12: 690 | E12: Combustível | F12: Transporte | G12: Realizado
A13: 45671 | B13: Transporte | C13: Estacionamento | D13: 230 | E13: Estacionamento | F13: Transporte | G13: Realizado
A14: 45681 | B14: Transporte | C14: Uber / Táxi | D14: 230 | E14: Transporte app | F14: Transporte | G14: Realizado
A15: 45666 | B15: Saúde | C15: Plano de Saúde | D15: 525 | E15: Mensalidade plano | F15: Saude | G15: Realizado
... A243: 46015 | B243: Outros | C243: Diversos | D243: 1200 | E243: Gastos diversos | F243: Outros | G243: Realizado

Sheet LAN_CARTOES
A1: 💳 LANÇAMENTOS DE CARTÕES DE CRÉDITO | J1: ⚠️ PARCELAS PENDENTES: | K1: =COUNTIF(I:I,"⚠️ Pendente") -> 0 | L1: =IF(K1=0,"✅ Tudo OK!","⚠️ Gerar parcelas!") -> ✅ Tudo OK!
A2: Compras Parceladas e à Vista no Crédito - Parcelas Geradas Automaticamente
A3: 📅 Data Compra | B3: 📂 Categoria | C3: 📋 Subcategoria | D3: 📝 Descrição | E3: 💳 Valor Total | F3: 🔢 Parcelas | G3: 💳 Cartão | H3: Categoria_Aux | I3: 📊 Status_Parcelas
A4: 45662 | B4: Alimentação | C4: Restaurante | D4: Jantar aniversário família | E4: 450 | F4: 1 | G4: Crédito Banco A - Maria | H4: =IF(tbCartoes[[#This Row],[📂 Categoria]]="","",SUBSTITUTE(tbCartoes[[#This Row],[📂 Categoria]]," ","_")) -> Alimentação | I4: =IF(A4="","",IF(COUNTIFS(tbParcelas6[Data_Compra],A4,tbParcelas6[Descrição],D4)>0,"✅ Gerada","⚠️ Pendente")) -> ✅ Gerada
A5: 45667 | B5: Vestuário | C5: Roupas | D5: Roupas de verão | E5: 890 | F5: 3 | G5: Crédito Banco A - Carlos | H5: =IF(tbCartoes[[#This Row],[📂 Categoria]]="","",SUBSTITUTE(tbCartoes[[#This Row],[📂 Categoria]]," ","_")) -> Vestuário | I5: =IF(A5="","",IF(COUNTIFS(tbParcelas6[Data_Compra],A5,tbParcelas6[Descrição],D5)>0,"✅ Gerada","⚠️ Pendente")) -> ✅ Gerada
A6: 45672 | B6: Lazer | C6: Viagem | D6: Passagens férias julho | E6: 3600 | F6: 6 | G6: Crédito Banco B - Maria | H6: =IF(tbCartoes[[#This Row],[📂 Categoria]]="","",SUBSTITUTE(tbCartoes[[#This Row],[📂 Categoria]]," ","_")) -> Lazer | I6: =IF(A6="","",IF(COUNTIFS(tbParcelas6[Data_Compra],A6,tbParcelas6[Descrição],D6)>0,"✅ Gerada","⚠️ Pendente")) -> ✅ Gerada
A7: 45677 | B7: Habitação | C7: Móveis / Decoração | D7: Sofá novo sala | E7: 4500 | F7: 10 | G7: Crédito Banco A - Maria | H7: =IF(tbCartoes[[#This Row],[📂 Categoria]]="","",SUBSTITUTE(tbCartoes[[#This Row],[📂 Categoria]]," ","_")) -> Habitação | I7: =IF(A7="","",IF(COUNTIFS(tbParcelas6[Data_Compra],A7,tbParcelas6[Descrição],D7)>0,"✅ Gerada","⚠️ Pendente")) -> ✅ Gerada
A8: 45691 | B8: Educação | C8: Cursos | D8: Curso online Excel | E8: 297 | F8: 1 | G8: Crédito Banco A - Carlos | H8: =IF(tbCartoes[[#This Row],[📂 Categoria]]="","",SUBSTITUTE(tbCartoes[[#This Row],[📂 Categoria]]," ","_")) -> Educação | I8: =IF(A8="","",IF(COUNTIFS(tbParcelas6[Data_Compra],A8,tbParcelas6[Descrição],D8)>0,"✅ Gerada","⚠️ Pendente")) -> ✅ Gerada
A9: 45702 | B9: Lazer | C9: Saídas | D9: Jantar Dia dos Namorados | E9: 380 | F9: 1 | G9: Crédito Banco B - Maria | H9: =IF(tbCartoes[[#This Row],[📂 Categoria]]="","",SUBSTITUTE(tbCartoes[[#This Row],[📂 Categoria]]," ","_")) -> Lazer | I9: =IF(A9="","",IF(COUNTIFS(tbParcelas6[Data_Compra],A9,tbParcelas6[Descrição],D9)>0,"✅ Gerada","⚠️ Pendente")) -> ✅ Gerada
A10: 45708 | B10: Saúde | C10: Consultas / Exames | D10: Óculos novos | E10: 1200 | F10: 4 | G10: Crédito Banco A - Maria | H10: =IF(tbCartoes[[#This Row],[📂 Categoria]]="","",SUBSTITUTE(tbCartoes[[#This Row],[📂 Categoria]]," ","_")) -> Saúde | I10: =IF(A10="","",IF(COUNTIFS(tbParcelas6[Data_Compra],A10,tbParcelas6[Descrição],D10)>0,"✅ Gerada","⚠️ Pendente")) -> ✅ Gerada
A11: 45721 | B11: Transporte | C11: Manutenção Veículo | D11: Revisão carro | E11: 1850 | F11: 3 | G11: Crédito Banco A - Carlos | H11: =IF(tbCartoes[[#This Row],[📂 Categoria]]="","",SUBSTITUTE(tbCartoes[[#This Row],[📂 Categoria]]," ","_")) -> Transporte | I11: =IF(A11="","",IF(COUNTIFS(tbParcelas6[Data_Compra],A11,tbParcelas6[Descrição],D11)>0,"✅ Gerada","⚠️ Pendente")) -> ✅ Gerada
A12: 45728 | B12: Alimentação | C12: Supermercado | D12: Compra grande mensal | E12: 650 | F12: 1 | G12: Crédito Banco B - Maria | H12: =IF(tbCartoes[[#This Row],[📂 Categoria]]="","",SUBSTITUTE(tbCartoes[[#This Row],[📂 Categoria]]," ","_")) -> Alimentação | I12: =IF(A12="","",IF(COUNTIFS(tbParcelas6[Data_Compra],A12,tbParcelas6[Descrição],D12)>0,"✅ Gerada","⚠️ Pendente")) -> ✅ Gerada
A13: 45741 | B13: Habitação | C13: Eletrodomésticos | D13: Geladeira nova | E13: 3200 | F13: 10 | G13: Crédito Banco A - Maria | H13: =IF(tbCartoes[[#This Row],[📂 Categoria]]="","",SUBSTITUTE(tbCartoes[[#This Row],[📂 Categoria]]," ","_")) -> Habitação | I13: =IF(A13="","",IF(COUNTIFS(tbParcelas6[Data_Compra],A13,tbParcelas6[Descrição],D13)>0,"✅ Gerada","⚠️ Pendente")) -> ✅ Gerada
A14: 45755 | B14: Vestuário | C14: Calçados | D14: Tênis corrida | E14: 590 | F14: 2 | G14: Crédito Banco A - Carlos | H14: =IF(tbCartoes[[#This Row],[📂 Categoria]]="","",SUBSTITUTE(tbCartoes[[#This Row],[📂 Categoria]]," ","_")) -> Vestuário | I14: =IF(A14="","",IF(COUNTIFS(tbParcelas6[Data_Compra],A14,tbParcelas6[Descrição],D14)>0,"✅ Gerada","⚠️ Pendente")) -> ✅ Gerada
A15: 45762 | B15: Lazer | C15: Streaming (Netflix/Spotify/Prime) | D15: Assinatura anual Disney+ | E15: 360 | F15: 1 | G15: Crédito Banco B - Maria | H15: =IF(tbCartoes[[#This Row],[📂 Categoria]]="","",SUBSTITUTE(tbCartoes[[#This Row],[📂 Categoria]]," ","_")) -> Lazer | I15: =IF(A15="","",IF(COUNTIFS(tbParcelas6[Data_Compra],A15,tbParcelas6[Descrição],D15)>0,"✅ Gerada","⚠️ Pendente")) -> ✅ Gerada
... A40: 46011 | B40: Lazer | C40: Saídas | D40: Festa Réveillon | E40: 450 | F40: 2 | G40: Crédito Banco A - Maria | H40: =IF(tbCartoes[[#This Row],[📂 Categoria]]="","",SUBSTITUTE(tbCartoes[[#This Row],[📂 Categoria]]," ","_")) -> Lazer | I40: =IF(A40="","",IF(COUNTIFS(tbParcelas6[Data_Compra],A40,tbParcelas6[Descrição],D40)>0,"✅ Gerada","⚠️ Pendente")) -> ✅ Gerada
H41: =IF(tbCartoes[[#This Row],[📂 Categoria]]="","",SUBSTITUTE(tbCartoes[[#This Row],[📂 Categoria]]," ","_"))
H42: =IF(tbCartoes[[#This Row],[📂 Categoria]]="","",SUBSTITUTE(tbCartoes[[#This Row],[📂 Categoria]]," ","_"))
H43: =IF(tbCartoes[[#This Row],[📂 Categoria]]="","",SUBSTITUTE(tbCartoes[[#This Row],[📂 Categoria]]," ","_"))
H44: =IF(tbCartoes[[#This Row],[📂 Categoria]]="","",SUBSTITUTE(tbCartoes[[#This Row],[📂 Categoria]]," ","_"))
H45: =IF(tbCartoes[[#This Row],[📂 Categoria]]="","",SUBSTITUTE(tbCartoes[[#This Row],[📂 Categoria]]," ","_"))
H46: =IF(tbCartoes[[#This Row],[📂 Categoria]]="","",SUBSTITUTE(tbCartoes[[#This Row],[📂 Categoria]]," ","_"))
H47: =IF(tbCartoes[[#This Row],[📂 Categoria]]="","",SUBSTITUTE(tbCartoes[[#This Row],[📂 Categoria]]," ","_"))
H48: =IF(tbCartoes[[#This Row],[📂 Categoria]]="","",SUBSTITUTE(tbCartoes[[#This Row],[📂 Categoria]]," ","_"))
H49: =IF(tbCartoes[[#This Row],[📂 Categoria]]="","",SUBSTITUTE(tbCartoes[[#This Row],[📂 Categoria]]," ","_"))
H50: =IF(tbCartoes[[#This Row],[📂 Categoria]]="","",SUBSTITUTE(tbCartoes[[#This Row],[📂 Categoria]]," ","_"))
H51: =IF(tbCartoes[[#This Row],[📂 Categoria]]="","",SUBSTITUTE(tbCartoes[[#This Row],[📂 Categoria]]," ","_"))
H52: =IF(tbCartoes[[#This Row],[📂 Categoria]]="","",SUBSTITUTE(tbCartoes[[#This Row],[📂 Categoria]]," ","_"))
... H1004: =IF(tbCartoes[[#This Row],[📂 Categoria]]="","",SUBSTITUTE(tbCartoes[[#This Row],[📂 Categoria]]," ","_"))

Sheet FLUXO_CAIXA
A1: 📊 FLUXO DE CAIXA: REALIZADO + PREVISTO | K1: {=INDEX($G$7:$G$18,MONTH(TODAY())-1)} -> 17146.333
K2: {=SUMPRODUCT((tb_receitas[📅 Data]>=DATE(YEAR(TODAY()),MONTH(TODAY()),1))*(tb_receitas[📅 Data]<TODAY())*(tb_receitas[📊 Status]="Realizado")*(tb_receitas[💵 Valor]))} -> 0
A3: 📅 ANO: | B3: 2025 | D3: 📆 MÊS: | E3: 0 | G3: (0 = Todos | 1-12 = Mês específico) | I3: 📅 Data Ref: | J3: =DATE($B$3,5,18) -> 45795 | K3: {=SUMPRODUCT((tbDespesas[📅 Data]>=DATE(YEAR(TODAY()),MONTH(TODAY()),1))*(tbDespesas[📅 Data]<TODAY())*(tbDespesas[📊 Status]="Realizado")*(tbDespesas[💰 Valor]))} -> 0
A4: 💰 SALDO EM 01/01: | B4: 10000 | C4: (Saldo bancário em 1º de janeiro do ano selecionado) | K4: {=SUMPRODUCT((tbParcelas6[Data_Vencimento]>=DATE(YEAR(TODAY()),MONTH(TODAY()),1))*(tbParcelas6[Data_Vencimento]<TODAY())*(tbParcelas6[Valor_Parcela]))} -> 0
K5: =K1+K2-K3-K4 -> 17146.333
A6: Mês | B6: Entradas Reais | C6: Entradas Previstas | D6: Saídas Reais | E6: Saídas Previstas | F6: Saldo Mês | G6: Saldo Acum. | H6: Status | K6: {=SUMPRODUCT((tb_investimentos[Data]>=DATE(YEAR(TODAY()),MONTH(TODAY()),1))*(tb_investimentos[Data]<TODAY())*(tb_investimentos[Movimento]="Aporte")*(tb_investimentos[Valor]))} -> 0
A7: ="jan/"&$B$3 -> jan/2025 | B7: =SUMIFS(tb_receitas[💵 Valor],tb_receitas[📅 Data],">="&DATE($B$3,1,1),tb_receitas[📅 Data],"<"&DATE($B$3,1+1,1),tb_receitas[📊 Status],"Realizado")+SUMIFS(tb_investimentos[Valor],tb_investimentos[Data],">="&DATE($B$3,1,1),tb_investimentos[Data],"<"&DATE($B$3,1+1,1),tb_investimentos[Movimento],"Resgate") -> 16200 | C7: {=SUMPRODUCT((tbPrevisoes[📂 TIPO]="Receita")*(tbPrevisoes[✅ STATUS]="Ativa")*(YEAR(tbPrevisoes[📅 DATA])=$B$3)*(MONTH(tbPrevisoes[📅 DATA])=1)*tbPrevisoes[💰 VALOR])} -> 0 | D7: =SUMIFS(tbDespesas[💰 Valor],tbDespesas[📅 Data],">="&DATE($B$3,1,1),tbDespesas[📅 Data],"<"&DATE($B$3,1+1,1),tbDespesas[📊 Status],"Realizado")+SUMIFS(tbParcelas6[Valor_Parcela],tbParcelas6[Data_Vencimento],">="&DATE($B$3,1,1),tbParcelas6[Data_Vencimento],"<"&DATE($B$3,1+1,1)) -> 12580 | E7: {=SUMPRODUCT((tbPrevisoes[📂 TIPO]="Despesa")*(tbPrevisoes[✅ STATUS]="Ativa")*(YEAR(tbPrevisoes[📅 DATA])=$B$3)*(MONTH(tbPrevisoes[📅 DATA])=1)*tbPrevisoes[💰 VALOR])} -> 0 | F7: =(B7+C7)-(D7+E7) -> 3620 | G7: =$B$4+F7 -> 13620 | H7: =IF(G7<0,"🔴 Negativo",IF(G7<5000,"🟡 Alerta","🟢 OK")) -> 🟢 OK
A8: ="fev/"&$B$3 -> fev/2025 | B8: =SUMIFS(tb_receitas[💵 Valor],tb_receitas[📅 Data],">="&DATE($B$3,2,1),tb_receitas[📅 Data],"<"&DATE($B$3,2+1,1),tb_receitas[📊 Status],"Realizado")+SUMIFS(tb_investimentos[Valor],tb_investimentos[Data],">="&DATE($B$3,2,1),tb_investimentos[Data],"<"&DATE($B$3,2+1,1),tb_investimentos[Movimento],"Resgate") -> 15900 | C8: {=SUMPRODUCT((tbPrevisoes[📂 TIPO]="Receita")*(tbPrevisoes[✅ STATUS]="Ativa")*(YEAR(tbPrevisoes[📅 DATA])=$B$3)*(MONTH(tbPrevisoes[📅 DATA])=2)*tbPrevisoes[💰 VALOR])} -> 0 | D8: =SUMIFS(tbDespesas[💰 Valor],tbDespesas[📅 Data],">="&DATE($B$3,2,1),tbDespesas[📅 Data],"<"&DATE($B$3,2+1,1),tbDespesas[📊 Status],"Realizado")+SUMIFS(tbParcelas6[Valor_Parcela],tbParcelas6[Data_Vencimento],">="&DATE($B$3,2,1),tbParcelas6[Data_Vencimento],"<"&DATE($B$3,2+1,1)) -> 14366.667 | E8: {=SUMPRODUCT((tbPrevisoes[📂 TIPO]="Despesa")*(tbPrevisoes[✅ STATUS]="Ativa")*(YEAR(tbPrevisoes[📅 DATA])=$B$3)*(MONTH(tbPrevisoes[📅 DATA])=2)*tbPrevisoes[💰 VALOR])} -> 0 | F8: =(B8+C8)-(D8+E8) -> 1533.3333 | G8: =G7+F8 -> 15153.333 | H8: =IF(G8<0,"🔴 Negativo",IF(G8<5000,"🟡 Alerta","🟢 OK")) -> 🟢 OK
A9: ="mar/"&$B$3 -> mar/2025 | B9: =SUMIFS(tb_receitas[💵 Valor],tb_receitas[📅 Data],">="&DATE($B$3,3,1),tb_receitas[📅 Data],"<"&DATE($B$3,3+1,1),tb_receitas[📊 Status],"Realizado")+SUMIFS(tb_investimentos[Valor],tb_investimentos[Data],">="&DATE($B$3,3,1),tb_investimentos[Data],"<"&DATE($B$3,3+1,1),tb_investimentos[Movimento],"Resgate") -> 16400 | C9: {=SUMPRODUCT((tbPrevisoes[📂 TIPO]="Receita")*(tbPrevisoes[✅ STATUS]="Ativa")*(YEAR(tbPrevisoes[📅 DATA])=$B$3)*(MONTH(tbPrevisoes[📅 DATA])=3)*tbPrevisoes[💰 VALOR])} -> 0 | D9: =SUMIFS(tbDespesas[💰 Valor],tbDespesas[📅 Data],">="&DATE($B$3,3,1),tbDespesas[📅 Data],"<"&DATE($B$3,3+1,1),tbDespesas[📊 Status],"Realizado")+SUMIFS(tbParcelas6[Valor_Parcela],tbParcelas6[Data_Vencimento],">="&DATE($B$3,3,1),tbParcelas6[Data_Vencimento],"<"&DATE($B$3,3+1,1)) -> 14073.667 | E9: {=SUMPRODUCT((tbPrevisoes[📂 TIPO]="Despesa")*(tbPrevisoes[✅ STATUS]="Ativa")*(YEAR(tbPrevisoes[📅 DATA])=$B$3)*(MONTH(tbPrevisoes[📅 DATA])=3)*tbPrevisoes[💰 VALOR])} -> 0 | F9: =(B9+C9)-(D9+E9) -> 2326.3333 | G9: =G8+F9 -> 17479.667 | H9: =IF(G9<0,"🔴 Negativo",IF(G9<5000,"🟡 Alerta","🟢 OK")) -> 🟢 OK
A10: ="abr/"&$B$3 -> abr/2025 | B10: =SUMIFS(tb_receitas[💵 Valor],tb_receitas[📅 Data],">="&DATE($B$3,4,1),tb_receitas[📅 Data],"<"&DATE($B$3,4+1,1),tb_receitas[📊 Status],"Realizado")+SUMIFS(tb_investimentos[Valor],tb_investimentos[Data],">="&DATE($B$3,4,1),tb_investimentos[Data],"<"&DATE($B$3,4+1,1),tb_investimentos[Movimento],"Resgate") -> 16000 | C10: {=SUMPRODUCT((tbPrevisoes[📂 TIPO]="Receita")*(tbPrevisoes[✅ STATUS]="Ativa")*(YEAR(tbPrevisoes[📅 DATA])=$B$3)*(MONTH(tbPrevisoes[📅 DATA])=4)*tbPrevisoes[💰 VALOR])} -> 0 | D10: =SUMIFS(tbDespesas[💰 Valor],tbDespesas[📅 Data],">="&DATE($B$3,4,1),tbDespesas[📅 Data],"<"&DATE($B$3,4+1,1),tbDespesas[📊 Status],"Realizado")+SUMIFS(tbParcelas6[Valor_Parcela],tbParcelas6[Data_Vencimento],">="&DATE($B$3,4,1),tbParcelas6[Data_Vencimento],"<"&DATE($B$3,4+1,1)) -> 16333.333 | E10: {=SUMPRODUCT((tbPrevisoes[📂 TIPO]="Despesa")*(tbPrevisoes[✅ STATUS]="Ativa")*(YEAR(tbPrevisoes[📅 DATA])=$B$3)*(MONTH(tbPrevisoes[📅 DATA])=4)*tbPrevisoes[💰 VALOR])} -> 0 | F10: =(B10+C10)-(D10+E10) -> -333.33333 | G10: =G9+F10 -> 17146.333 | H10: =IF(G10<0,"🔴 Negativo",IF(G10<5000,"🟡 Alerta","🟢 OK")) -> 🟢 OK
A11: ="mai/"&$B$3 -> mai/2025 | B11: =SUMIFS(tb_receitas[💵 Valor],tb_receitas[📅 Data],">="&DATE($B$3,5,1),tb_receitas[📅 Data],"<"&DATE($B$3,5+1,1),tb_receitas[📊 Status],"Realizado")+SUMIFS(tb_investimentos[Valor],tb_investimentos[Data],">="&DATE($B$3,5,1),tb_investimentos[Data],"<"&DATE($B$3,5+1,1),tb_investimentos[Movimento],"Resgate") -> 16150 | C11: {=SUMPRODUCT((tbPrevisoes[📂 TIPO]="Receita")*(tbPrevisoes[✅ STATUS]="Ativa")*(YEAR(tbPrevisoes[📅 DATA])=$B$3)*(MONTH(tbPrevisoes[📅 DATA])=5)*tbPrevisoes[💰 VALOR])} -> 0 | D11: =SUMIFS(tbDespesas[💰 Valor],tbDespesas[📅 Data],">="&DATE($B$3,5,1),tbDespesas[📅 Data],"<"&DATE($B$3,5+1,1),tbDespesas[📊 Status],"Realizado")+SUMIFS(tbParcelas6[Valor_Parcela],tbParcelas6[Data_Vencimento],">="&DATE($B$3,5,1),tbParcelas6[Data_Vencimento],"<"&DATE($B$3,5+1,1)) -> 15681.667 | E11: {=SUMPRODUCT((tbPrevisoes[📂 TIPO]="Despesa")*(tbPrevisoes[✅ STATUS]="Ativa")*(YEAR(tbPrevisoes[📅 DATA])=$B$3)*(MONTH(tbPrevisoes[📅 DATA])=5)*tbPrevisoes[💰 VALOR])} -> 0 | F11: =(B11+C11)-(D11+E11) -> 468.33333 | G11: =G10+F11 -> 17614.667 | H11: =IF(G11<0,"🔴 Negativo",IF(G11<5000,"🟡 Alerta","🟢 OK")) -> 🟢 OK
A12: ="jun/"&$B$3 -> jun/2025 | B12: =SUMIFS(tb_receitas[💵 Valor],tb_receitas[📅 Data],">="&DATE($B$3,6,1),tb_receitas[📅 Data],"<"&DATE($B$3,6+1,1),tb_receitas[📊 Status],"Realizado")+SUMIFS(tb_investimentos[Valor],tb_investimentos[Data],">="&DATE($B$3,6,1),tb_investimentos[Data],"<"&DATE($B$3,6+1,1),tb_investimentos[Movimento],"Resgate") -> 15950 | C12: {=SUMPRODUCT((tbPrevisoes[📂 TIPO]="Receita")*(tbPrevisoes[✅ STATUS]="Ativa")*(YEAR(tbPrevisoes[📅 DATA])=$B$3)*(MONTH(tbPrevisoes[📅 DATA])=6)*tbPrevisoes[💰 VALOR])} -> 0 | D12: =SUMIFS(tbDespesas[💰 Valor],tbDespesas[📅 Data],">="&DATE($B$3,6,1),tbDespesas[📅 Data],"<"&DATE($B$3,6+1,1),tbDespesas[📊 Status],"Realizado")+SUMIFS(tbParcelas6[Valor_Parcela],tbParcelas6[Data_Vencimento],">="&DATE($B$3,6,1),tbParcelas6[Data_Vencimento],"<"&DATE($B$3,6+1,1)) -> 16428.333 | E12: {=SUMPRODUCT((tbPrevisoes[📂 TIPO]="Despesa")*(tbPrevisoes[✅ STATUS]="Ativa")*(YEAR(tbPrevisoes[📅 DATA])=$B$3)*(MONTH(tbPrevisoes[📅 DATA])=6)*tbPrevisoes[💰 VALOR])} -> 0 | F12: =(B12+C12)-(D12+E12) -> -478.33333 | G12: =G11+F12 -> 17136.333 | H12: =IF(G12<0,"🔴 Negativo",IF(G12<5000,"🟡 Alerta","🟢 OK")) -> 🟢 OK
A13: ="jul/"&$B$3 -> jul/2025 | B13: =SUMIFS(tb_receitas[💵 Valor],tb_receitas[📅 Data],">="&DATE($B$3,7,1),tb_receitas[📅 Data],"<"&DATE($B$3,7+1,1),tb_receitas[📊 Status],"Realizado")+SUMIFS(tb_investimentos[Valor],tb_investimentos[Data],">="&DATE($B$3,7,1),tb_investimentos[Data],"<"&DATE($B$3,7+1,1),tb_investimentos[Movimento],"Resgate") -> 16000 | C13: {=SUMPRODUCT((tbPrevisoes[📂 TIPO]="Receita")*(tbPrevisoes[✅ STATUS]="Ativa")*(YEAR(tbPrevisoes[📅 DATA])=$B$3)*(MONTH(tbPrevisoes[📅 DATA])=7)*tbPrevisoes[💰 VALOR])} -> 0 | D13: =SUMIFS(tbDespesas[💰 Valor],tbDespesas[📅 Data],">="&DATE($B$3,7,1),tbDespesas[📅 Data],"<"&DATE($B$3,7+1,1),tbDespesas[📊 Status],"Realizado")+SUMIFS(tbParcelas6[Valor_Parcela],tbParcelas6[Data_Vencimento],">="&DATE($B$3,7,1),tbParcelas6[Data_Vencimento],"<"&DATE($B$3,7+1,1)) -> 16341.667 | E13: {=SUMPRODUCT((tbPrevisoes[📂 TIPO]="Despesa")*(tbPrevisoes[✅ STATUS]="Ativa")*(YEAR(tbPrevisoes[📅 DATA])=$B$3)*(MONTH(tbPrevisoes[📅 DATA])=7)*tbPrevisoes[💰 VALOR])} -> 0 | F13: =(B13+C13)-(D13+E13) -> -341.66667 | G13: =G12+F13 -> 16794.667 | H13: =IF(G13<0,"🔴 Negativo",IF(G13<5000,"🟡 Alerta","🟢 OK")) -> 🟢 OK | K13: {=SUMPRODUCT((tbDespesas[📅 Data]>=DATE(2026,5,1))*(tbDespesas[📅 Data]<TODAY())*(tbDespesas[📊 Status]="Realizado")*(tbDespesas[💰 Valor]))} -> 0
A14: ="ago/"&$B$3 -> ago/2025 | B14: =SUMIFS(tb_receitas[💵 Valor],tb_receitas[📅 Data],">="&DATE($B$3,8,1),tb_receitas[📅 Data],"<"&DATE($B$3,8+1,1),tb_receitas[📊 Status],"Realizado")+SUMIFS(tb_investimentos[Valor],tb_investimentos[Data],">="&DATE($B$3,8,1),tb_investimentos[Data],"<"&DATE($B$3,8+1,1),tb_investimentos[Movimento],"Resgate") -> 16250 | C14: {=SUMPRODUCT((tbPrevisoes[📂 TIPO]="Receita")*(tbPrevisoes[✅ STATUS]="Ativa")*(YEAR(tbPrevisoes[📅 DATA])=$B$3)*(MONTH(tbPrevisoes[📅 DATA])=8)*tbPrevisoes[💰 VALOR])} -> 0 | D14: =SUMIFS(tbDespesas[💰 Valor],tbDespesas[📅 Data],">="&DATE($B$3,8,1),tbDespesas[📅 Data],"<"&DATE($B$3,8+1,1),tbDespesas[📊 Status],"Realizado")+SUMIFS(tbParcelas6[Valor_Parcela],tbParcelas6[Data_Vencimento],">="&DATE($B$3,8,1),tbParcelas6[Data_Vencimento],"<"&DATE($B$3,8+1,1)) -> 14511.667 | E14: {=SUMPRODUCT((tbPrevisoes[📂 TIPO]="Despesa")*(tbPrevisoes[✅ STATUS]="Ativa")*(YEAR(tbPrevisoes[📅 DATA])=$B$3)*(MONTH(tbPrevisoes[📅 DATA])=8)*tbPrevisoes[💰 VALOR])} -> 0 | F14: =(B14+C14)-(D14+E14) -> 1738.3333 | G14: =G13+F14 -> 18533 | H14: =IF(G14<0,"🔴 Negativo",IF(G14<5000,"🟡 Alerta","🟢 OK")) -> 🟢 OK | K14: {=SUMPRODUCT((tbParcelas6[Data_Vencimento]>=DATE(2026,5,1))*(tbParcelas6[Data_Vencimento]<TODAY())*(tbParcelas6[Valor_Parcela]))} -> 0
A15: ="set/"&$B$3 -> set/2025 | B15: =SUMIFS(tb_receitas[💵 Valor],tb_receitas[📅 Data],">="&DATE($B$3,9,1),tb_receitas[📅 Data],"<"&DATE($B$3,9+1,1),tb_receitas[📊 Status],"Realizado")+SUMIFS(tb_investimentos[Valor],tb_investimentos[Data],">="&DATE($B$3,9,1),tb_investimentos[Data],"<"&DATE($B$3,9+1,1),tb_investimentos[Movimento],"Resgate") -> 16050 | C15: {=SUMPRODUCT((tbPrevisoes[📂 TIPO]="Receita")*(tbPrevisoes[✅ STATUS]="Ativa")*(YEAR(tbPrevisoes[📅 DATA])=$B$3)*(MONTH(tbPrevisoes[📅 DATA])=9)*tbPrevisoes[💰 VALOR])} -> 0 | D15: =SUMIFS(tbDespesas[💰 Valor],tbDespesas[📅 Data],">="&DATE($B$3,9,1),tbDespesas[📅 Data],"<"&DATE($B$3,9+1,1),tbDespesas[📊 Status],"Realizado")+SUMIFS(tbParcelas6[Valor_Parcela],tbParcelas6[Data_Vencimento],">="&DATE($B$3,9,1),tbParcelas6[Data_Vencimento],"<"&DATE($B$3,9+1,1)) -> 15540 | E15: {=SUMPRODUCT((tbPrevisoes[📂 TIPO]="Despesa")*(tbPrevisoes[✅ STATUS]="Ativa")*(YEAR(tbPrevisoes[📅 DATA])=$B$3)*(MONTH(tbPrevisoes[📅 DATA])=9)*tbPrevisoes[💰 VALOR])} -> 0 | F15: =(B15+C15)-(D15+E15) -> 510 | G15: =G14+F15 -> 19043 | H15: =IF(G15<0,"🔴 Negativo",IF(G15<5000,"🟡 Alerta","🟢 OK")) -> 🟢 OK | K15: {=SUMPRODUCT((tb_investimentos[Data]>=DATE(2026,5,1))*(tb_investimentos[Data]<TODAY())*(tb_investimentos[Movimento]="Aporte")*(tb_investimentos[Valor]))-SUMPRODUCT((tb_investimentos[Data]>=DATE(2026,5,1))*(tb_investimentos[Data]<TODAY())*(tb_investimentos[Movimento]="Resgate")*(tb_investimentos[Valor]))} -> 0
A16: ="out/"&$B$3 -> out/2025 | B16: =SUMIFS(tb_receitas[💵 Valor],tb_receitas[📅 Data],">="&DATE($B$3,10,1),tb_receitas[📅 Data],"<"&DATE($B$3,10+1,1),tb_receitas[📊 Status],"Realizado")+SUMIFS(tb_investimentos[Valor],tb_investimentos[Data],">="&DATE($B$3,10,1),tb_investimentos[Data],"<"&DATE($B$3,10+1,1),tb_investimentos[Movimento],"Resgate") -> 16000 | C16: {=SUMPRODUCT((tbPrevisoes[📂 TIPO]="Receita")*(tbPrevisoes[✅ STATUS]="Ativa")*(YEAR(tbPrevisoes[📅 DATA])=$B$3)*(MONTH(tbPrevisoes[📅 DATA])=10)*tbPrevisoes[💰 VALOR])} -> 0 | D16: =SUMIFS(tbDespesas[💰 Valor],tbDespesas[📅 Data],">="&DATE($B$3,10,1),tbDespesas[📅 Data],"<"&DATE($B$3,10+1,1),tbDespesas[📊 Status],"Realizado")+SUMIFS(tbParcelas6[Valor_Parcela],tbParcelas6[Data_Vencimento],">="&DATE($B$3,10,1),tbParcelas6[Data_Vencimento],"<"&DATE($B$3,10+1,1)) -> 15770 | E16: {=SUMPRODUCT((tbPrevisoes[📂 TIPO]="Despesa")*(tbPrevisoes[✅ STATUS]="Ativa")*(YEAR(tbPrevisoes[📅 DATA])=$B$3)*(MONTH(tbPrevisoes[📅 DATA])=10)*tbPrevisoes[💰 VALOR])} -> 0 | F16: =(B16+C16)-(D16+E16) -> 230 | G16: =G15+F16 -> 19273 | H16: =IF(G16<0,"🔴 Negativo",IF(G16<5000,"🟡 Alerta","🟢 OK")) -> 🟢 OK
A17: ="nov/"&$B$3 -> nov/2025 | B17: =SUMIFS(tb_receitas[💵 Valor],tb_receitas[📅 Data],">="&DATE($B$3,11,1),tb_receitas[📅 Data],"<"&DATE($B$3,11+1,1),tb_receitas[📊 Status],"Realizado")+SUMIFS(tb_investimentos[Valor],tb_investimentos[Data],">="&DATE($B$3,11,1),tb_investimentos[Data],"<"&DATE($B$3,11+1,1),tb_investimentos[Movimento],"Resgate") -> 16500 | C17: {=SUMPRODUCT((tbPrevisoes[📂 TIPO]="Receita")*(tbPrevisoes[✅ STATUS]="Ativa")*(YEAR(tbPrevisoes[📅 DATA])=$B$3)*(MONTH(tbPrevisoes[📅 DATA])=11)*tbPrevisoes[💰 VALOR])} -> 0 | D17: =SUMIFS(tbDespesas[💰 Valor],tbDespesas[📅 Data],">="&DATE($B$3,11,1),tbDespesas[📅 Data],"<"&DATE($B$3,11+1,1),tbDespesas[📊 Status],"Realizado")+SUMIFS(tbParcelas6[Valor_Parcela],tbParcelas6[Data_Vencimento],">="&DATE($B$3,11,1),tbParcelas6[Data_Vencimento],"<"&DATE($B$3,11+1,1)) -> 14956.667 | E17: {=SUMPRODUCT((tbPrevisoes[📂 TIPO]="Despesa")*(tbPrevisoes[✅ STATUS]="Ativa")*(YEAR(tbPrevisoes[📅 DATA])=$B$3)*(MONTH(tbPrevisoes[📅 DATA])=11)*tbPrevisoes[💰 VALOR])} -> 0 | F17: =(B17+C17)-(D17+E17) -> 1543.3333 | G17: =G16+F17 -> 20816.333 | H17: =IF(G17<0,"🔴 Negativo",IF(G17<5000,"🟡 Alerta","🟢 OK")) -> 🟢 OK
A18: ="dez/"&$B$3 -> dez/2025 | B18: =SUMIFS(tb_receitas[💵 Valor],tb_receitas[📅 Data],">="&DATE($B$3,12,1),tb_receitas[📅 Data],"<"&DATE($B$3,12+1,1),tb_receitas[📊 Status],"Realizado")+SUMIFS(tb_investimentos[Valor],tb_investimentos[Data],">="&DATE($B$3,12,1),tb_investimentos[Data],"<"&DATE($B$3,12+1,1),tb_investimentos[Movimento],"Resgate") -> 16600 | C18: {=SUMPRODUCT((tbPrevisoes[📂 TIPO]="Receita")*(tbPrevisoes[✅ STATUS]="Ativa")*(YEAR(tbPrevisoes[📅 DATA])=$B$3)*(MONTH(tbPrevisoes[📅 DATA])=12)*tbPrevisoes[💰 VALOR])} -> 0 | D18: =SUMIFS(tbDespesas[💰 Valor],tbDespesas[📅 Data],">="&DATE($B$3,12,1),tbDespesas[📅 Data],"<"&DATE($B$3,12+1,1),tbDespesas[📊 Status],"Realizado")+SUMIFS(tbParcelas6[Valor_Parcela],tbParcelas6[Data_Vencimento],">="&DATE($B$3,12,1),tbParcelas6[Data_Vencimento],"<"&DATE($B$3,12+1,1)) -> 16706.667 | E18: {=SUMPRODUCT((tbPrevisoes[📂 TIPO]="Despesa")*(tbPrevisoes[✅ STATUS]="Ativa")*(YEAR(tbPrevisoes[📅 DATA])=$B$3)*(MONTH(tbPrevisoes[📅 DATA])=12)*tbPrevisoes[💰 VALOR])} -> 0 | F18: =(B18+C18)-(D18+E18) -> -106.66667 | G18: =G17+F18 -> 20709.667 | H18: =IF(G18<0,"🔴 Negativo",IF(G18<5000,"🟡 Alerta","🟢 OK")) -> 🟢 OK
A19: TOTAL ANUAL | B19: =SUM(B7:B18) -> 194000 | C19: =SUM(C7:C18) -> 0 | D19: =SUM(D7:D18) -> 183290.33 | E19: =SUM(E7:E18) -> 0 | F19: =(B19+C19)-(D19+E19) -> 10709.667 | G19: =G18 -> 20709.667
A21: 📊 FLUXO DE CAIXA - PRÓXIMOS 30 DIAS
B22: 💰 SALDO INICIAL: R$ | C22: {=IFERROR(INDEX(G$7:G$18,MATCH(EOMONTH($J$3,-1),A$7:A$18,0)),$B$4)+SUMPRODUCT((tb_receitas[📅 Data]>=DATE(YEAR($J$3),MONTH($J$3),1))*(tb_receitas[📅 Data]<$J$3)*(tb_receitas[📊 Status]="Realizado")*(tb_receitas[💵 Valor]))-SUMPRODUCT((tbDespesas[📅 Data]>=DATE(YEAR($J$3),MONTH($J$3),1))*(tbDespesas[📅 Data]<$J$3)*(tbDespesas[📊 Status]="Realizado")*(tbDespesas[💰 Valor]))-SUMPRODUCT((tbParcelas6[Data_Vencimento]>=DATE(YEAR($J$3),MONTH($J$3),1))*(tbParcelas6[Data_Vencimento]<$J$3)*(tbParcelas6[Valor_Parcela]))} -> 14468.333
A23: # | B23: 📅 Data | C23: 📆 Dia | D23: 💰 Entradas | E23: 📉 Saídas | F23: 💵 Saldo Dia | G23: 📊 Saldo Acum. | I23: 🎨 LEGENDA
A24: 1 | B24: =$J$3+0 -> 45795 | C24: =TEXT(B24,"ddd") -> dom | D24: {=SUMPRODUCT((tb_receitas[📅 Data]=$B24)*(tb_receitas[📊 Status]="Realizado")*tb_receitas[💵 Valor])+SUMPRODUCT((tb_receitas[📅 Data]=$B24)*(tb_receitas[📊 Status]="Previsto")*tb_receitas[💵 Valor])+SUMPRODUCT((tbPrevisoes[📅 DATA]=$B24)*(tbPrevisoes[📂 TIPO]="Receita")*(tbPrevisoes[✅ STATUS]="Ativa")*tbPrevisoes[💰 VALOR])} -> 0 | E24: {=SUMPRODUCT((tbDespesas[📅 Data]=$B24)*(tbDespesas[📊 Status]="Realizado")*tbDespesas[💰 Valor])+SUMPRODUCT((tbDespesas[📅 Data]=$B24)*(tbDespesas[📊 Status]="Previsto")*tbDespesas[💰 Valor])+SUMPRODUCT((tbParcelas6[Data_Vencimento]=$B24)*tbParcelas6[Valor_Parcela])+SUMPRODUCT((tbPrevisoes[📅 DATA]=$B24)*(tbPrevisoes[📂 TIPO]="Despesa")*(tbPrevisoes[✅ STATUS]="Ativa")*tbPrevisoes[💰 VALOR])} -> 0 | F24: =D24-E24 -> 0 | G24: =$C$22+F24 -> 14468.333 | H24: =IF(B24=TODAY(),"📅","")
A25: 2 | B25: =$J$3+1 -> 45796 | C25: =TEXT(B25,"ddd") -> seg | D25: {=SUMPRODUCT((tb_receitas[📅 Data]=$B25)*(tb_receitas[📊 Status]="Realizado")*tb_receitas[💵 Valor])+SUMPRODUCT((tb_receitas[📅 Data]=$B25)*(tb_receitas[📊 Status]="Previsto")*tb_receitas[💵 Valor])+SUMPRODUCT((tbPrevisoes[📅 DATA]=$B25)*(tbPrevisoes[📂 TIPO]="Receita")*(tbPrevisoes[✅ STATUS]="Ativa")*tbPrevisoes[💰 VALOR])} -> 0 | E25: {=SUMPRODUCT((tbDespesas[📅 Data]=$B25)*(tbDespesas[📊 Status]="Realizado")*tbDespesas[💰 Valor])+SUMPRODUCT((tbDespesas[📅 Data]=$B25)*(tbDespesas[📊 Status]="Previsto")*tbDespesas[💰 Valor])+SUMPRODUCT((tbParcelas6[Data_Vencimento]=$B25)*tbParcelas6[Valor_Parcela])+SUMPRODUCT((tbPrevisoes[📅 DATA]=$B25)*(tbPrevisoes[📂 TIPO]="Despesa")*(tbPrevisoes[✅ STATUS]="Ativa")*tbPrevisoes[💰 VALOR])} -> 1104 | F25: =D25-E25 -> -1104 | G25: =G24+F25 -> 13364.333 | H25: =IF(B25=TODAY(),"📅","")
A26: 3 | B26: =$J$3+2 -> 45797 | C26: =TEXT(B26,"ddd") -> ter | D26: {=SUMPRODUCT((tb_receitas[📅 Data]=$B26)*(tb_receitas[📊 Status]="Realizado")*tb_receitas[💵 Valor])+SUMPRODUCT((tb_receitas[📅 Data]=$B26)*(tb_receitas[📊 Status]="Previsto")*tb_receitas[💵 Valor])+SUMPRODUCT((tbPrevisoes[📅 DATA]=$B26)*(tbPrevisoes[📂 TIPO]="Receita")*(tbPrevisoes[✅ STATUS]="Ativa")*tbPrevisoes[💰 VALOR])} -> 0 | E26: {=SUMPRODUCT((tbDespesas[📅 Data]=$B26)*(tbDespesas[📊 Status]="Realizado")*tbDespesas[💰 Valor])+SUMPRODUCT((tbDespesas[📅 Data]=$B26)*(tbDespesas[📊 Status]="Previsto")*tbDespesas[💰 Valor])+SUMPRODUCT((tbParcelas6[Data_Vencimento]=$B26)*tbParcelas6[Valor_Parcela])+SUMPRODUCT((tbPrevisoes[📅 DATA]=$B26)*(tbPrevisoes[📂 TIPO]="Despesa")*(tbPrevisoes[✅ STATUS]="Ativa")*tbPrevisoes[💰 VALOR])} -> 0 | F26: =D26-E26 -> 0 | G26: =G25+F26 -> 13364.333 | H26: =IF(B26=TODAY(),"📅","")
A27: 4 | B27: =$J$3+3 -> 45798 | C27: =TEXT(B27,"ddd") -> qua | D27: {=SUMPRODUCT((tb_receitas[📅 Data]=$B27)*(tb_receitas[📊 Status]="Realizado")*tb_receitas[💵 Valor])+SUMPRODUCT((tb_receitas[📅 Data]=$B27)*(tb_receitas[📊 Status]="Previsto")*tb_receitas[💵 Valor])+SUMPRODUCT((tbPrevisoes[📅 DATA]=$B27)*(tbPrevisoes[📂 TIPO]="Receita")*(tbPrevisoes[✅ STATUS]="Ativa")*tbPrevisoes[💰 VALOR])} -> 0 | E27: {=SUMPRODUCT((tbDespesas[📅 Data]=$B27)*(tbDespesas[📊 Status]="Realizado")*tbDespesas[💰 Valor])+SUMPRODUCT((tbDespesas[📅 Data]=$B27)*(tbDespesas[📊 Status]="Previsto")*tbDespesas[💰 Valor])+SUMPRODUCT((tbParcelas6[Data_Vencimento]=$B27)*tbParcelas6[Valor_Parcela])+SUMPRODUCT((tbPrevisoes[📅 DATA]=$B27)*(tbPrevisoes[📂 TIPO]="Despesa")*(tbPrevisoes[✅ STATUS]="Ativa")*tbPrevisoes[💰 VALOR])} -> 300 | F27: =D27-E27 -> -300 | G27: =G26+F27 -> 13064.333 | H27: =IF(B27=TODAY(),"📅","")
A28: 5 | B28: =$J$3+4 -> 45799 | C28: =TEXT(B28,"ddd") -> qui | D28: {=SUMPRODUCT((tb_receitas[📅 Data]=$B28)*(tb_receitas[📊 Status]="Realizado")*tb_receitas[💵 Valor])+SUMPRODUCT((tb_receitas[📅 Data]=$B28)*(tb_receitas[📊 Status]="Previsto")*tb_receitas[💵 Valor])+SUMPRODUCT((tbPrevisoes[📅 DATA]=$B28)*(tbPrevisoes[📂 TIPO]="Receita")*(tbPrevisoes[✅ STATUS]="Ativa")*tbPrevisoes[💰 VALOR])} -> 0 | E28: {=SUMPRODUCT((tbDespesas[📅 Data]=$B28)*(tbDespesas[📊 Status]="Realizado")*tbDespesas[💰 Valor])+SUMPRODUCT((tbDespesas[📅 Data]=$B28)*(tbDespesas[📊 Status]="Previsto")*tbDespesas[💰 Valor])+SUMPRODUCT((tbParcelas6[Data_Vencimento]=$B28)*tbParcelas6[Valor_Parcela])+SUMPRODUCT((tbPrevisoes[📅 DATA]=$B28)*(tbPrevisoes[📂 TIPO]="Despesa")*(tbPrevisoes[✅ STATUS]="Ativa")*tbPrevisoes[💰 VALOR])} -> 0 | F28: =D28-E28 -> 0 | G28: =G27+F28 -> 13064.333 | H28: =IF(B28=TODAY(),"📅","")
A29: 6 | B29: =$J$3+5 -> 45800 | C29: =TEXT(B29,"ddd") -> sex | D29: {=SUMPRODUCT((tb_receitas[📅 Data]=$B29)*(tb_receitas[📊 Status]="Realizado")*tb_receitas[💵 Valor])+SUMPRODUCT((tb_receitas[📅 Data]=$B29)*(tb_receitas[📊 Status]="Previsto")*tb_receitas[💵 Valor])+SUMPRODUCT((tbPrevisoes[📅 DATA]=$B29)*(tbPrevisoes[📂 TIPO]="Receita")*(tbPrevisoes[✅ STATUS]="Ativa")*tbPrevisoes[💰 VALOR])} -> 0 | E29: {=SUMPRODUCT((tbDespesas[📅 Data]=$B29)*(tbDespesas[📊 Status]="Realizado")*tbDespesas[💰 Valor])+SUMPRODUCT((tbDespesas[📅 Data]=$B29)*(tbDespesas[📊 Status]="Previsto")*tbDespesas[💰 Valor])+SUMPRODUCT((tbParcelas6[Data_Vencimento]=$B29)*tbParcelas6[Valor_Parcela])+SUMPRODUCT((tbPrevisoes[📅 DATA]=$B29)*(tbPrevisoes[📂 TIPO]="Despesa")*(tbPrevisoes[✅ STATUS]="Ativa")*tbPrevisoes[💰 VALOR])} -> 0 | F29: =D29-E29 -> 0 | G29: =G28+F29 -> 13064.333 | H29: =IF(B29=TODAY(),"📅","")
A30: 7 | B30: =$J$3+6 -> 45801 | C30: =TEXT(B30,"ddd") -> sáb | D30: {=SUMPRODUCT((tb_receitas[📅 Data]=$B30)*(tb_receitas[📊 Status]="Realizado")*tb_receitas[💵 Valor])+SUMPRODUCT((tb_receitas[📅 Data]=$B30)*(tb_receitas[📊 Status]="Previsto")*tb_receitas[💵 Valor])+SUMPRODUCT((tbPrevisoes[📅 DATA]=$B30)*(tbPrevisoes[📂 TIPO]="Receita")*(tbPrevisoes[✅ STATUS]="Ativa")*tbPrevisoes[💰 VALOR])} -> 500 | E30: {=SUMPRODUCT((tbDespesas[📅 Data]=$B30)*(tbDespesas[📊 Status]="Realizado")*tbDespesas[💰 Valor])+SUMPRODUCT((tbDespesas[📅 Data]=$B30)*(tbDespesas[📊 Status]="Previsto")*tbDespesas[💰 Valor])+SUMPRODUCT((tbParcelas6[Data_Vencimento]=$B30)*tbParcelas6[Valor_Parcela])+SUMPRODUCT((tbPrevisoes[📅 DATA]=$B30)*(tbPrevisoes[📂 TIPO]="Despesa")*(tbPrevisoes[✅ STATUS]="Ativa")*tbPrevisoes[💰 VALOR])} -> 1816 | F30: =D30-E30 -> -1316 | G30: =G29+F30 -> 11748.333 | H30: =IF(B30=TODAY(),"📅","")
A31: 8 | B31: =$J$3+7 -> 45802 | C31: =TEXT(B31,"ddd") -> dom | D31: {=SUMPRODUCT((tb_receitas[📅 Data]=$B31)*(tb_receitas[📊 Status]="Realizado")*tb_receitas[💵 Valor])+SUMPRODUCT((tb_receitas[📅 Data]=$B31)*(tb_receitas[📊 Status]="Previsto")*tb_receitas[💵 Valor])+SUMPRODUCT((tbPrevisoes[📅 DATA]=$B31)*(tbPrevisoes[📂 TIPO]="Receita")*(tbPrevisoes[✅ STATUS]="Ativa")*tbPrevisoes[💰 VALOR])} -> 0 | E31: {=SUMPRODUCT((tbDespesas[📅 Data]=$B31)*(tbDespesas[📊 Status]="Realizado")*tbDespesas[💰 Valor])+SUMPRODUCT((tbDespesas[📅 Data]=$B31)*(tbDespesas[📊 Status]="Previsto")*tbDespesas[💰 Valor])+SUMPRODUCT((tbParcelas6[Data_Vencimento]=$B31)*tbParcelas6[Valor_Parcela])+SUMPRODUCT((tbPrevisoes[📅 DATA]=$B31)*(tbPrevisoes[📂 TIPO]="Despesa")*(tbPrevisoes[✅ STATUS]="Ativa")*tbPrevisoes[💰 VALOR])} -> 0 | F31: =D31-E31 -> 0 | G31: =G30+F31 -> 11748.333 | H31: =IF(B31=TODAY(),"📅","")
A32: 9 | B32: =$J$3+8 -> 45803 | C32: =TEXT(B32,"ddd") -> seg | D32: {=SUMPRODUCT((tb_receitas[📅 Data]=$B32)*(tb_receitas[📊 Status]="Realizado")*tb_receitas[💵 Valor])+SUMPRODUCT((tb_receitas[📅 Data]=$B32)*(tb_receitas[📊 Status]="Previsto")*tb_receitas[💵 Valor])+SUMPRODUCT((tbPrevisoes[📅 DATA]=$B32)*(tbPrevisoes[📂 TIPO]="Receita")*(tbPrevisoes[✅ STATUS]="Ativa")*tbPrevisoes[💰 VALOR])} -> 0 | E32: {=SUMPRODUCT((tbDespesas[📅 Data]=$B32)*(tbDespesas[📊 Status]="Realizado")*tbDespesas[💰 Valor])+SUMPRODUCT((tbDespesas[📅 Data]=$B32)*(tbDespesas[📊 Status]="Previsto")*tbDespesas[💰 Valor])+SUMPRODUCT((tbParcelas6[Data_Vencimento]=$B32)*tbParcelas6[Valor_Parcela])+SUMPRODUCT((tbPrevisoes[📅 DATA]=$B32)*(tbPrevisoes[📂 TIPO]="Despesa")*(tbPrevisoes[✅ STATUS]="Ativa")*tbPrevisoes[💰 VALOR])} -> 0 | F32: =D32-E32 -> 0 | G32: =G31+F32 -> 11748.333 | H32: =IF(B32=TODAY(),"📅","")
A33: 10 | B33: =$J$3+9 -> 45804 | C33: =TEXT(B33,"ddd") -> ter | D33: {=SUMPRODUCT((tb_receitas[📅 Data]=$B33)*(tb_receitas[📊 Status]="Realizado")*tb_receitas[💵 Valor])+SUMPRODUCT((tb_receitas[📅 Data]=$B33)*(tb_receitas[📊 Status]="Previsto")*tb_receitas[💵 Valor])+SUMPRODUCT((tbPrevisoes[📅 DATA]=$B33)*(tbPrevisoes[📂 TIPO]="Receita")*(tbPrevisoes[✅ STATUS]="Ativa")*tbPrevisoes[💰 VALOR])} -> 0 | E33: {=SUMPRODUCT((tbDespesas[📅 Data]=$B33)*(tbDespesas[📊 Status]="Realizado")*tbDespesas[💰 Valor])+SUMPRODUCT((tbDespesas[📅 Data]=$B33)*(tbDespesas[📊 Status]="Previsto")*tbDespesas[💰 Valor])+SUMPRODUCT((tbParcelas6[Data_Vencimento]=$B33)*tbParcelas6[Valor_Parcela])+SUMPRODUCT((tbPrevisoes[📅 DATA]=$B33)*(tbPrevisoes[📂 TIPO]="Despesa")*(tbPrevisoes[✅ STATUS]="Ativa")*tbPrevisoes[💰 VALOR])} -> 720 | F33: =D33-E33 -> -720 | G33: =G32+F33 -> 11028.333 | H33: =IF(B33=TODAY(),"📅","")
A34: 11 | B34: =$J$3+10 -> 45805 | C34: =TEXT(B34,"ddd") -> qua | D34: {=SUMPRODUCT((tb_receitas[📅 Data]=$B34)*(tb_receitas[📊 Status]="Realizado")*tb_receitas[💵 Valor])+SUMPRODUCT((tb_receitas[📅 Data]=$B34)*(tb_receitas[📊 Status]="Previsto")*tb_receitas[💵 Valor])+SUMPRODUCT((tbPrevisoes[📅 DATA]=$B34)*(tbPrevisoes[📂 TIPO]="Receita")*(tbPrevisoes[✅ STATUS]="Ativa")*tbPrevisoes[💰 VALOR])} -> 0 | E34: {=SUMPRODUCT((tbDespesas[📅 Data]=$B34)*(tbDespesas[📊 Status]="Realizado")*tbDespesas[💰 Valor])+SUMPRODUCT((tbDespesas[📅 Data]=$B34)*(tbDespesas[📊 Status]="Previsto")*tbDespesas[💰 Valor])+SUMPRODUCT((tbParcelas6[Data_Vencimento]=$B34)*tbParcelas6[Valor_Parcela])+SUMPRODUCT((tbPrevisoes[📅 DATA]=$B34)*(tbPrevisoes[📂 TIPO]="Despesa")*(tbPrevisoes[✅ STATUS]="Ativa")*tbPrevisoes[💰 VALOR])} -> 0 | F34: =D34-E34 -> 0 | G34: =G33+F34 -> 11028.333 | H34: =IF(B34=TODAY(),"📅","")
A35: 12 | B35: =$J$3+11 -> 45806 | C35: =TEXT(B35,"ddd") -> qui | D35: {=SUMPRODUCT((tb_receitas[📅 Data]=$B35)*(tb_receitas[📊 Status]="Realizado")*tb_receitas[💵 Valor])+SUMPRODUCT((tb_receitas[📅 Data]=$B35)*(tb_receitas[📊 Status]="Previsto")*tb_receitas[💵 Valor])+SUMPRODUCT((tbPrevisoes[📅 DATA]=$B35)*(tbPrevisoes[📂 TIPO]="Receita")*(tbPrevisoes[✅ STATUS]="Ativa")*tbPrevisoes[💰 VALOR])} -> 0 | E35: {=SUMPRODUCT((tbDespesas[📅 Data]=$B35)*(tbDespesas[📊 Status]="Realizado")*tbDespesas[💰 Valor])+SUMPRODUCT((tbDespesas[📅 Data]=$B35)*(tbDespesas[📊 Status]="Previsto")*tbDespesas[💰 Valor])+SUMPRODUCT((tbParcelas6[Data_Vencimento]=$B35)*tbParcelas6[Valor_Parcela])+SUMPRODUCT((tbPrevisoes[📅 DATA]=$B35)*(tbPrevisoes[📂 TIPO]="Despesa")*(tbPrevisoes[✅ STATUS]="Ativa")*tbPrevisoes[💰 VALOR])} -> 0 | F35: =D35-E35 -> 0 | G35: =G34+F35 -> 11028.333 | H35: =IF(B35=TODAY(),"📅","")
A36: 13 | B36: =$J$3+12 -> 45807 | C36: =TEXT(B36,"ddd") -> sex | D36: {=SUMPRODUCT((tb_receitas[📅 Data]=$B36)*(tb_receitas[📊 Status]="Realizado")*tb_receitas[💵 Valor])+SUMPRODUCT((tb_receitas[📅 Data]=$B36)*(tb_receitas[📊 Status]="Previsto")*tb_receitas[💵 Valor])+SUMPRODUCT((tbPrevisoes[📅 DATA]=$B36)*(tbPrevisoes[📂 TIPO]="Receita")*(tbPrevisoes[✅ STATUS]="Ativa")*tbPrevisoes[💰 VALOR])} -> 0 | E36: {=SUMPRODUCT((tbDespesas[📅 Data]=$B36)*(tbDespesas[📊 Status]="Realizado")*tbDespesas[💰 Valor])+SUMPRODUCT((tbDespesas[📅 Data]=$B36)*(tbDespesas[📊 Status]="Previsto")*tbDespesas[💰 Valor])+SUMPRODUCT((tbParcelas6[Data_Vencimento]=$B36)*tbParcelas6[Valor_Parcela])+SUMPRODUCT((tbPrevisoes[📅 DATA]=$B36)*(tbPrevisoes[📂 TIPO]="Despesa")*(tbPrevisoes[✅ STATUS]="Ativa")*tbPrevisoes[💰 VALOR])} -> 0 | F36: =D36-E36 -> 0 | G36: =G35+F36 -> 11028.333 | H36: =IF(B36=TODAY(),"📅","")
A37: 14 | B37: =$J$3+13 -> 45808 | C37: =TEXT(B37,"ddd") -> sáb | D37: {=SUMPRODUCT((tb_receitas[📅 Data]=$B37)*(tb_receitas[📊 Status]="Realizado")*tb_receitas[💵 Valor])+SUMPRODUCT((tb_receitas[📅 Data]=$B37)*(tb_receitas[📊 Status]="Previsto")*tb_receitas[💵 Valor])+SUMPRODUCT((tbPrevisoes[📅 DATA]=$B37)*(tbPrevisoes[📂 TIPO]="Receita")*(tbPrevisoes[✅ STATUS]="Ativa")*tbPrevisoes[💰 VALOR])} -> 500 | E37: {=SUMPRODUCT((tbDespesas[📅 Data]=$B37)*(tbDespesas[📊 Status]="Realizado")*tbDespesas[💰 Valor])+SUMPRODUCT((tbDespesas[📅 Data]=$B37)*(tbDespesas[📊 Status]="Previsto")*tbDespesas[💰 Valor])+SUMPRODUCT((tbParcelas6[Data_Vencimento]=$B37)*tbParcelas6[Valor_Parcela])+SUMPRODUCT((tbPrevisoes[📅 DATA]=$B37)*(tbPrevisoes[📂 TIPO]="Despesa")*(tbPrevisoes[✅ STATUS]="Ativa")*tbPrevisoes[💰 VALOR])} -> 100 | F37: =D37-E37 -> 400 | G37: =G36+F37 -> 11428.333 | H37: =IF(B37=TODAY(),"📅","")
A38: 15 | B38: =$J$3+14 -> 45809 | C38: =TEXT(B38,"ddd") -> dom | D38: {=SUMPRODUCT((tb_receitas[📅 Data]=$B38)*(tb_receitas[📊 Status]="Realizado")*tb_receitas[💵 Valor])+SUMPRODUCT((tb_receitas[📅 Data]=$B38)*(tb_receitas[📊 Status]="Previsto")*tb_receitas[💵 Valor])+SUMPRODUCT((tbPrevisoes[📅 DATA]=$B38)*(tbPrevisoes[📂 TIPO]="Receita")*(tbPrevisoes[✅ STATUS]="Ativa")*tbPrevisoes[💰 VALOR])} -> 0 | E38: {=SUMPRODUCT((tbDespesas[📅 Data]=$B38)*(tbDespesas[📊 Status]="Realizado")*tbDespesas[💰 Valor])+SUMPRODUCT((tbDespesas[📅 Data]=$B38)*(tbDespesas[📊 Status]="Previsto")*tbDespesas[💰 Valor])+SUMPRODUCT((tbParcelas6[Data_Vencimento]=$B38)*tbParcelas6[Valor_Parcela])+SUMPRODUCT((tbPrevisoes[📅 DATA]=$B38)*(tbPrevisoes[📂 TIPO]="Despesa")*(tbPrevisoes[✅ STATUS]="Ativa")*tbPrevisoes[💰 VALOR])} -> 0 | F38: =D38-E38 -> 0 | G38: =G37+F38 -> 11428.333 | H38: =IF(B38=TODAY(),"📅","")
A39: 16 | B39: =$J$3+15 -> 45810 | C39: =TEXT(B39,"ddd") -> seg | D39: {=SUMPRODUCT((tb_receitas[📅 Data]=$B39)*(tb_receitas[📊 Status]="Realizado")*tb_receitas[💵 Valor])+SUMPRODUCT((tb_receitas[📅 Data]=$B39)*(tb_receitas[📊 Status]="Previsto")*tb_receitas[💵 Valor])+SUMPRODUCT((tbPrevisoes[📅 DATA]=$B39)*(tbPrevisoes[📂 TIPO]="Receita")*(tbPrevisoes[✅ STATUS]="Ativa")*tbPrevisoes[💰 VALOR])} -> 0 | E39: {=SUMPRODUCT((tbDespesas[📅 Data]=$B39)*(tbDespesas[📊 Status]="Realizado")*tbDespesas[💰 Valor])+SUMPRODUCT((tbDespesas[📅 Data]=$B39)*(tbDespesas[📊 Status]="Previsto")*tbDespesas[💰 Valor])+SUMPRODUCT((tbParcelas6[Data_Vencimento]=$B39)*tbParcelas6[Valor_Parcela])+SUMPRODUCT((tbPrevisoes[📅 DATA]=$B39)*(tbPrevisoes[📂 TIPO]="Despesa")*(tbPrevisoes[✅ STATUS]="Ativa")*tbPrevisoes[💰 VALOR])} -> 0 | F39: =D39-E39 -> 0 | G39: =G38+F39 -> 11428.333 | H39: =IF(B39=TODAY(),"📅","")
A40: 17 | B40: =$J$3+16 -> 45811 | C40: =TEXT(B40,"ddd") -> ter | D40: {=SUMPRODUCT((tb_receitas[📅 Data]=$B40)*(tb_receitas[📊 Status]="Realizado")*tb_receitas[💵 Valor])+SUMPRODUCT((tb_receitas[📅 Data]=$B40)*(tb_receitas[📊 Status]="Previsto")*tb_receitas[💵 Valor])+SUMPRODUCT((tbPrevisoes[📅 DATA]=$B40)*(tbPrevisoes[📂 TIPO]="Receita")*(tbPrevisoes[✅ STATUS]="Ativa")*tbPrevisoes[💰 VALOR])} -> 0 | E40: {=SUMPRODUCT((tbDespesas[📅 Data]=$B40)*(tbDespesas[📊 Status]="Realizado")*tbDespesas[💰 Valor])+SUMPRODUCT((tbDespesas[📅 Data]=$B40)*(tbDespesas[📊 Status]="Previsto")*tbDespesas[💰 Valor])+SUMPRODUCT((tbParcelas6[Data_Vencimento]=$B40)*tbParcelas6[Valor_Parcela])+SUMPRODUCT((tbPrevisoes[📅 DATA]=$B40)*(tbPrevisoes[📂 TIPO]="Despesa")*(tbPrevisoes[✅ STATUS]="Ativa")*tbPrevisoes[💰 VALOR])} -> 0 | F40: =D40-E40 -> 0 | G40: =G39+F40 -> 11428.333 | H40: =IF(B40=TODAY(),"📅","")
A41: 18 | B41: =$J$3+17 -> 45812 | C41: =TEXT(B41,"ddd") -> qua | D41: {=SUMPRODUCT((tb_receitas[📅 Data]=$B41)*(tb_receitas[📊 Status]="Realizado")*tb_receitas[💵 Valor])+SUMPRODUCT((tb_receitas[📅 Data]=$B41)*(tb_receitas[📊 Status]="Previsto")*tb_receitas[💵 Valor])+SUMPRODUCT((tbPrevisoes[📅 DATA]=$B41)*(tbPrevisoes[📂 TIPO]="Receita")*(tbPrevisoes[✅ STATUS]="Ativa")*tbPrevisoes[💰 VALOR])} -> 8500 | E41: {=SUMPRODUCT((tbDespesas[📅 Data]=$B41)*(tbDespesas[📊 Status]="Realizado")*tbDespesas[💰 Valor])+SUMPRODUCT((tbDespesas[📅 Data]=$B41)*(tbDespesas[📊 Status]="Previsto")*tbDespesas[💰 Valor])+SUMPRODUCT((tbParcelas6[Data_Vencimento]=$B41)*tbParcelas6[Valor_Parcela])+SUMPRODUCT((tbPrevisoes[📅 DATA]=$B41)*(tbPrevisoes[📂 TIPO]="Despesa")*(tbPrevisoes[✅ STATUS]="Ativa")*tbPrevisoes[💰 VALOR])} -> 2886 | F41: =D41-E41 -> 5614 | G41: =G40+F41 -> 17042.333 | H41: =IF(B41=TODAY(),"📅","")
...

Sheet DASHBOARD
A1: 📊 DASHBOARD - ORÇAMENTO DOMÉSTICO | P1: 📋 DADOS AUXILIARES (não ocultar - usados pelos gráficos)
A2: Controle Financeiro Pessoal
A4: 📅 ANO: | B4: 2025 | D4: 📆 MÊS: | E4: 0 | G4: (0 = Ano completo | 1-12 = Mês específico)
A6: 💰 RECEITAS | D6: 📉 DESPESAS | G6: 💵 SALDO | J6: 📈 INVESTIMENTOS | M6: 📊 % ECONOMIA
A7: {=SUMPRODUCT((YEAR(tb_receitas[📅 Data])=$B$4)*(IF($E$4=0,1,MONTH(tb_receitas[📅 Data])=$E$4))*tb_receitas[💵 Valor])+SUMPRODUCT((YEAR(tbPrevisoes[📅 DATA])=$B$4)*(IF($E$4=0,1,MONTH(tbPrevisoes[📅 DATA])=$E$4))*(tbPrevisoes[📂 TIPO]="Receita")*(tbPrevisoes[✅ STATUS]="Ativa")*tbPrevisoes[💰 VALOR])} -> 194000 | D7: {=SUMPRODUCT((YEAR(tbDespesas[📅 Data])=$B$4)*(IF($E$4=0,1,MONTH(tbDespesas[📅 Data])=$E$4))*(tbDespesas[📊 Status]="Realizado")*tbDespesas[💰 Valor])+SUMPRODUCT((YEAR(tbParcelas6[Data_Vencimento])=$B$4)*(IF($E$4=0,1,MONTH(tbParcelas6[Data_Vencimento])=$E$4))*tbParcelas6[Valor_Parcela])+SUMPRODUCT((YEAR(tbPrevisoes[📅 DATA])=$B$4)*(IF($E$4=0,1,MONTH(tbPrevisoes[📅 DATA])=$E$4))*(tbPrevisoes[📂 TIPO]="Despesa")*(tbPrevisoes[✅ STATUS]="Ativa")*tbPrevisoes[💰 VALOR])} -> 183290.33 | G7: =A7-D7 -> 10709.667 | J7: {=SUMPRODUCT((YEAR(tb_investimentos[Data])=$B$4)*(IF($E$4=0,1,MONTH(tb_investimentos[Data])=$E$4))*(tb_investimentos[Movimento]="Aporte")*tb_investimentos[Valor])-SUMPRODUCT((YEAR(tb_investimentos[Data])=$B$4)*(IF($E$4=0,1,MONTH(tb_investimentos[Data])=$E$4))*(tb_investimentos[Movimento]="Resgate")*tb_investimentos[Valor])} -> 6200 | M7: =IF(A7=0,0,(A7-D7)/A7) -> 0.055204467
A22: 📋 ORÇADO vs REALIZADO
A23: Categoria | B23: Orçado | C23: Realizado | D23: Variação | E23: % Variação | F23: Status | P23: Categoria | Q23: Valor
A24: RECEITAS | B24: =IF($E$4=0,ORCAMENTO!$B$3*12,ORCAMENTO!$B$3) -> 192000 | C24: {=SUMPRODUCT((YEAR(tb_receitas[📅 Data])=$B$4)*(IF($E$4=0,1,MONTH(tb_receitas[📅 Data])=$E$4))*tb_receitas[💵 Valor])} -> 194000 | D24: =C24-B24 -> 2000 | E24: =IFERROR(D24/B24,0) -> 0.010416667 | F24: =IF(D24>=0,"✅ OK","⚠️ Abaixo") -> ✅ OK | P24: Habitação | Q24: =C32 -> 59508.333
A25: Salário | B25: =IF($E$4=0,ORCAMENTO!$B$4*12,ORCAMENTO!$B$4) -> 180000 | C25: {=SUMPRODUCT((tb_receitas[📂 Categoria]="Salário")*(YEAR(tb_receitas[📅 Data])=$B$4)*(IF($E$4=0,1,MONTH(tb_receitas[📅 Data])=$E$4))*tb_receitas[💵 Valor])} -> 180000 | D25: =C25-B25 -> 0 | E25: =IFERROR(D25/B25,0) -> 0 | F25: =IF(D25>=0,"✅","⚠️") -> ✅ | P25: Alimentação | Q25: =C33 -> 27450
A26: Benefício | B26: =IF($E$4=0,ORCAMENTO!$B$11*12,ORCAMENTO!$B$11) -> 6000 | C26: {=SUMPRODUCT((tb_receitas[📂 Categoria]="Benefício")*(YEAR(tb_receitas[📅 Data])=$B$4)*(IF($E$4=0,1,MONTH(tb_receitas[📅 Data])=$E$4))*tb_receitas[💵 Valor])} -> 5500 | D26: =C26-B26 -> -500 | E26: =IFERROR(D26/B26,0) -> -0.083333333 | F26: =IF(D26>=0,"✅","⚠️") -> ⚠️ | P26: Transporte | Q26: =C34 -> 15866.667
A27: Prestação Serviço Extra | B27: =IF($E$4=0,ORCAMENTO!$B$14*12,ORCAMENTO!$B$14) -> 6000 | C27: {=SUMPRODUCT((tb_receitas[📂 Categoria]="Prestação Serviço Extra")*(YEAR(tb_receitas[📅 Data])=$B$4)*(IF($E$4=0,1,MONTH(tb_receitas[📅 Data])=$E$4))*tb_receitas[💵 Valor])} -> 6100 | D27: =C27-B27 -> 100 | E27: =IFERROR(D27/B27,0) -> 0.016666667 | F27: =IF(D27>=0,"✅","⚠️") -> ✅ | P27: Saúde | Q27: =C35 -> 10765
A28: Convênios | B28: =IF($E$4=0,ORCAMENTO!$B$12*12,ORCAMENTO!$B$12) -> 0 | C28: {=SUMPRODUCT((tb_receitas[📂 Categoria]="Convênios")*(YEAR(tb_receitas[📅 Data])=$B$4)*(IF($E$4=0,1,MONTH(tb_receitas[📅 Data])=$E$4))*tb_receitas[💵 Valor])} -> 0 | D28: =C28-B28 -> 0 | E28: =IFERROR(D28/B28,0) -> 0 | F28: =IF(D28>=0,"✅","⚠️") -> ✅ | P28: Educação | Q28: =C36 -> 18917
A29: Extra | B29: =IF($E$4=0,ORCAMENTO!$B$13*12,ORCAMENTO!$B$13) -> 0 | C29: {=SUMPRODUCT((tb_receitas[📂 Categoria]="Extra")*(YEAR(tb_receitas[📅 Data])=$B$4)*(IF($E$4=0,1,MONTH(tb_receitas[📅 Data])=$E$4))*tb_receitas[💵 Valor])} -> 2400 | D29: =C29-B29 -> 2400 | E29: =IFERROR(D29/B29,0) -> 0 | F29: =IF(D29>=0,"✅","⚠️") -> ✅ | P29: Vestuário | Q29: =C37 -> 4971.6667
P30: Lazer | Q30: =C38 -> 10765
A31: DESPESAS | B31: =IF($E$4=0,ORCAMENTO!$B$20*12,ORCAMENTO!$B$20) -> 150000 | C31: {=SUMPRODUCT((YEAR(tbDespesas[📅 Data])=$B$4)*(IF($E$4=0,1,MONTH(tbDespesas[📅 Data])=$E$4))*tbDespesas[💰 Valor])+SUMPRODUCT((YEAR(tbParcelas6[Data_Vencimento])=$B$4)*(IF($E$4=0,1,MONTH(tbParcelas6[Data_Vencimento])=$E$4))*tbParcelas6[Valor_Parcela])} -> 183290.33 | D31: =B31-C31 -> -33290.333 | E31: =IF(B31=0,0,(B31-C31)/B31) -> -0.22193556 | F31: =IF(D31>=0,"✅ OK","🔴 Estouro") -> 🔴 Estouro | P31: Trabalho | Q31: =C39 -> 1150
A32: Habitação | B32: =IF($E$4=0,ORCAMENTO!$B$21*12,ORCAMENTO!$B$21) -> 57600 | C32: {=SUMPRODUCT((tbDespesas[📂 Categoria]="Habitação")*(YEAR(tbDespesas[📅 Data])=$B$4)*(IF($E$4=0,1,MONTH(tbDespesas[📅 Data])=$E$4))*(tbDespesas[📊 Status]="Realizado")*tbDespesas[💰 Valor])+SUMPRODUCT((tbCartoes[📂 Categoria]="Habitação")*(YEAR(tbCartoes[📅 Data Compra])=$B$4)*(IF($E$4=0,1,MONTH(tbCartoes[📅 Data Compra])=$E$4))*tbCartoes[💳 Valor Total]*IF(tbCartoes[🔢 Parcelas]=0,0,1/tbCartoes[🔢 Parcelas]))} -> 59508.333 | D32: =B32-C32 -> -1908.3333 | E32: =IFERROR(D32/B32,0) -> -0.033130787 | F32: =IF(D32>=0,"✅","🔴") -> 🔴 | P32: Caridade | Q32: =C40 -> 2450
